Workbook

Sheet Data
A1: thisN | B1: thisTrialN | C1: thisRepN | D1: key_resp.keys | E1: key_resp.corr | F1: key_resp.rt | G1: key_resp.duration | H1: tilt | I1: trials.thisRepN | J1: trials.thisTrialN | K1: trials.thisN | L1: trials.thisIndex | M1: thisRow.t | N1: notes | O1: piloting | P1: trial.started | Q1: fixation.started | R1: key_resp.started | S1: fixation.stopped | T1: trial.stopped | U1: trials.key_resp.keys | V1: trials.key_resp.corr | W1: trials.key_resp.rt | X1: trials.key_resp.duration | Y1: trials.tilt | Z1: participant | AA1: session | AB1: date | AC1: expName | AD1: expVersion | AE1: psychopyVersion | AF1: frameRate | AG1: expStart
A2: 0 | B2: 0 | C2: 0 | D2: up | E2: 1 | F2: 0.6967739 | H2: 0 | I2: 0 | J2: 0 | K2: 0 | L2: 0 | M2: 0.0102072 | O2: =FALSE() -> FALSE | P2: 0.0081043001 | Q2: 0.0102072 | R2: 0.9972784 | S2: 1.0002625 | T2: 1.7208488 | U2: up | V2: 1 | W2: 0.6967739 | Y2: 0 | Z2: 176374 | AA2: 1 | AB2: 2026-10-07_21h18.51.427 | AC2: orientation discriminatin task | AE2: 2026.2.4 | AF2: 119.92133 | AG2: 2026-10-07 21h18.51.473378 +0530
A3: 1 | B3: 0 | C3: 1 | D3: up | E3: 1 | F3: 0.5065839 | H3: 0 | I3: 1 | J3: 0 | K3: 1 | L3: 0 | M3: 1.7241438 | P3: 1.7211613 | Q3: 1.7241438 | R3: 2.7171828 | S3: 2.7171828 | T3: 3.2263058 | U3: up | V3: 1 | W3: 0.5065839 | Y3: 0 | Z3: 176374 | AA3: 1 | AB3: 2026-10-07_21h18.51.427 | AC3: orientation discriminatin task | AE3: 2026.2.4 | AF3: 119.92133 | AG3: 2026-10-07 21h18.51.473378 +0530
A4: 2 | B4: 0 | C4: 2 | D4: up | E4: 1 | F4: 0.4823019 | H4: 0 | I4: 2 | J4: 0 | K4: 2 | L4: 0 | M4: 3.2334198 | P4: 3.2267565 | Q4: 3.2334198 | R4: 4.2171825 | S4: 4.2255771 | T4: 4.7007524 | U4: up | V4: 1 | W4: 0.4823019 | Y4: 0 | Z4: 176374 | AA4: 1 | AB4: 2026-10-07_21h18.51.427 | AC4: orientation discriminatin task | AE4: 2026.2.4 | AF4: 119.92133 | AG4: 2026-10-07 21h18.51.473378 +0530
A5: 3 | B5: 0 | C5: 3 | D5: up | E5: 0 | F5: 0.4484925 | H5: 1 | I5: 3 | J5: 0 | K5: 3 | L5: 0 | M5: 4.708532 | P5: 4.701098 | Q5: 4.708532 | R5: 5.6916541 | S5: 5.7002355 | T5: 6.1423741 | U5: up | V5: 0 | W5: 0.4484925 | Y5: 1 | Z5: 176374 | AA5: 1 | AB5: 2026-10-07_21h18.51.427 | AC5: orientation discriminatin task | AE5: 2026.2.4 | AF5: 119.92133 | AG5: 2026-10-07 21h18.51.473378 +0530
A6: 4 | B6: 0 | C6: 4 | D6: down | E6: 1 | F6: 1.0388315 | H6: 4 | I6: 4 | J6: 0 | K6: 4 | L6: 0 | M6: 6.1500654 | P6: 6.1429929 | Q6: 6.1500654 | R6: 7.1334657 | S6: 7.1416461 | T6: 8.1757922 | U6: down | V6: 1 | W6: 1.0388315 | Y6: 4 | Z6: 176374 | AA6: 1 | AB6: 2026-10-07_21h18.51.427 | AC6: orientation discriminatin task | AE6: 2026.2.4 | AF6: 119.92133 | AG6: 2026-10-07 21h18.51.473378 +0530
A7: 5 | B7: 0 | C7: 5 | D7: up | E7: 0 | F7: 1.2293009 | H7: -1 | I7: 5 | J7: 0 | K7: 5 | L7: 0 | M7: 8.183488 | P7: 8.1762255 | Q7: 8.183488 | R7: 9.1666162 | S7: 9.1751839 | T7: 10.400675 | U7: up | V7: 0 | W7: 1.2293009 | Y7: -1 | Z7: 176374 | AA7: 1 | AB7: 2026-10-07_21h18.51.427 | AC7: orientation discriminatin task | AE7: 2026.2.4 | AF7: 119.92133 | AG7: 2026-10-07 21h18.51.473378 +0530
A8: 6 | B8: 0 | C8: 6 | D8: up | E8: 0 | F8: 0.7381575 | H8: -4 | I8: 6 | J8: 0 | K8: 6 | L8: 0 | M8: 10.408292 | P8: 10.4012 | Q8: 10.408292 | R8: 11.392739 | S8: 11.400509 | T8: 12.134123 | U8: up | V8: 0 | W8: 0.7381575 | Y8: -4 | Z8: 176374 | AA8: 1 | AB8: 2026-10-07_21h18.51.427 | AC8: orientation discriminatin task | AE8: 2026.2.4 | AF8: 119.92133 | AG8: 2026-10-07 21h18.51.473378 +0530
A9: 7 | B9: 0 | C9: 7 | D9: down | E9: 0 | F9: 1.7823934 | H9: 0 | I9: 7 | J9: 0 | K9: 7 | L9: 0 | M9: 12.141355 | P9: 12.134508 | Q9: 12.141355 | R9: 13.125033 | S9: 13.134329 | T9: 14.917216 | U9: down | V9: 0 | W9: 1.7823934 | Y9: 0 | Z9: 176374 | AA9: 1 | AB9: 2026-10-07_21h18.51.427 | AC9: orientation discriminatin task | AE9: 2026.2.4 | AF9: 119.92133 | AG9: 2026-10-07 21h18.51.473378 +0530
A10: 8 | B10: 0 | C10: 8 | D10: up | E10: 1 | F10: 0.8695993 | H10: 0 | I10: 8 | J10: 0 | K10: 8 | L10: 0 | M10: 14.925217 | P10: 14.917648 | Q10: 14.925217 | R10: 15.908696 | S10: 15.917038 | T10: 16.783735 | U10: up | V10: 1 | W10: 0.8695993 | Y10: 0 | Z10: 176374 | AA10: 1 | AB10: 2026-10-07_21h18.51.427 | AC10: orientation discriminatin task | AE10: 2026.2.4 | AF10: 119.92133 | AG10: 2026-10-07 21h18.51.473378 +0530
A11: 9 | B11: 0 | C11: 9 | D11: down | E11: 1 | F11: 1.1903221 | H11: 1 | I11: 9 | J11: 0 | K11: 9 | L11: 0 | M11: 16.791269 | P11: 16.78425 | Q11: 16.791269 | R11: 17.774934 | S11: 17.783661 | T11: 18.968265 | U11: down | V11: 1 | W11: 1.1903221 | Y11: 1 | Z11: 176374 | AA11: 1 | AB11: 2026-10-07_21h18.51.427 | AC11: orientation discriminatin task | AE11: 2026.2.4 | AF11: 119.92133 | AG11: 2026-10-07 21h18.51.473378 +0530
A12: 10 | B12: 0 | C12: 10 | D12: up | E12: 0 | F12: 1.488042 | H12: -2 | I12: 10 | J12: 0 | K12: 10 | L12: 0 | M12: 18.974836 | P12: 18.968716 | Q12: 18.974836 | R12: 19.967 | S12: 19.967 | T12: 21.458962 | U12: up | V12: 0 | W12: 1.488042 | Y12: -2 | Z12: 176374 | AA12: 1 | AB12: 2026-10-07_21h18.51.427 | AC12: orientation discriminatin task | AE12: 2026.2.4 | AF12: 119.92133 | AG12: 2026-10-07 21h18.51.473378 +0530
A13: 11 | B13: 0 | C13: 11 | D13: up | E13: 0 | F13: 1.1245813 | H13: -3 | I13: 11 | J13: 0 | K13: 11 | L13: 0 | M13: 21.466328 | P13: 21.459372 | Q13: 21.466328 | R13: 22.451119 | S13: 22.458039 | T13: 23.583641 | U13: up | V13: 0 | W13: 1.1245813 | Y13: -3 | Z13: 176374 | AA13: 1 | AB13: 2026-10-07_21h18.51.427 | AC13: orientation discriminatin task | AE13: 2026.2.4 | AF13: 119.92133 | AG13: 2026-10-07 21h18.51.473378 +0530
A14: 12 | B14: 0 | C14: 12 | D14: down | E14: 1 | F14: 0.4618531 | H14: 4 | I14: 12 | J14: 0 | K14: 12 | L14: 0 | M14: 23.591587 | P14: 23.583965 | Q14: 23.591587 | R14: 24.576008 | S14: 24.583126 | T14: 25.04316 | U14: down | V14: 1 | W14: 0.4618531 | Y14: 4 | Z14: 176374 | AA14: 1 | AB14: 2026-10-07_21h18.51.427 | AC14: orientation discriminatin task | AE14: 2026.2.4 | AF14: 119.92133 | AG14: 2026-10-07 21h18.51.473378 +0530
... A101: 99 | B101: 0 | C101: 99 | D101: up | E101: 0 | F101: 0.4433316 | H101: -4 | I101: 99 | J101: 0 | K101: 99 | L101: 0 | M101: 174.07035 | P101: 174.06373 | Q101: 174.07035 | R101: 175.06254 | S101: 175.06254 | T101: 175.51323 | U101: up | V101: 0 | W101: 0.4433316 | Y101: -4 | Z101: 176374 | AA101: 1 | AB101: 2026-10-07_21h18.51.427 | AC101: orientation discriminatin task | AE101: 2026.2.4 | AF101: 119.92133 | AG101: 2026-10-07 21h18.51.473378 +0530

Sheet Analysis
A1: Signal Detection Experiment – d' and Criterion (c) Analysis
A2: Source: PsychoPy output for participant 176374, session 1 (Data sheet). Green = pulled from Data sheet, black = calculated.
A3: Trial | B3: Tilt (deg) | C3: Size of tilt (deg) | D3: Key pressed | E3: Said "tilted" (1 = down key) | F3: Recorded correct (PsychoPy) | G3: Re-scored correct (rule) | H3: Outcome | I3: Recorded vs re-scored | K3: Signal detection summary | L3: Value
A4: =Data!A2+1 -> 1 | B4: =Data!H2 -> 0 | C4: =ABS(B4) -> 0 | D4: =Data!D2 -> up | E4: =IF(D4="down",1,0) -> 0 | F4: =Data!E2 -> 1 | G4: =IF(B4=0,1-E4,E4) -> 1 | H4: =IF(B4<>0,IF(E4=1,"Hit","Miss"),IF(E4=1,"False alarm","Correct rejection")) -> Correct rejection | I4: =IF(F4=G4,"","mismatch") | K4: Signal trials (tilt present) | L4: =COUNTIF(B4:B103,"<>0") -> 44
A5: =Data!A3+1 -> 2 | B5: =Data!H3 -> 0 | C5: =ABS(B5) -> 0 | D5: =Data!D3 -> up | E5: =IF(D5="down",1,0) -> 0 | F5: =Data!E3 -> 1 | G5: =IF(B5=0,1-E5,E5) -> 1 | H5: =IF(B5<>0,IF(E5=1,"Hit","Miss"),IF(E5=1,"False alarm","Correct rejection")) -> Correct rejection | I5: =IF(F5=G5,"","mismatch") | K5: Noise trials (no tilt, 0 deg) | L5: =COUNTIF(B4:B103,0) -> 56
A6: =Data!A4+1 -> 3 | B6: =Data!H4 -> 0 | C6: =ABS(B6) -> 0 | D6: =Data!D4 -> up | E6: =IF(D6="down",1,0) -> 0 | F6: =Data!E4 -> 1 | G6: =IF(B6=0,1-E6,E6) -> 1 | H6: =IF(B6<>0,IF(E6=1,"Hit","Miss"),IF(E6=1,"False alarm","Correct rejection")) -> Correct rejection | I6: =IF(F6=G6,"","mismatch") | K6: Hits (signal trial, said tilted) | L6: =COUNTIF(H4:H103,"Hit") -> 22
A7: =Data!A5+1 -> 4 | B7: =Data!H5 -> 1 | C7: =ABS(B7) -> 1 | D7: =Data!D5 -> up | E7: =IF(D7="down",1,0) -> 0 | F7: =Data!E5 -> 0 | G7: =IF(B7=0,1-E7,E7) -> 0 | H7: =IF(B7<>0,IF(E7=1,"Hit","Miss"),IF(E7=1,"False alarm","Correct rejection")) -> Miss | I7: =IF(F7=G7,"","mismatch") | K7: Misses (signal trial, said not tilted) | L7: =COUNTIF(H4:H103,"Miss") -> 22
A8: =Data!A6+1 -> 5 | B8: =Data!H6 -> 4 | C8: =ABS(B8) -> 4 | D8: =Data!D6 -> down | E8: =IF(D8="down",1,0) -> 1 | F8: =Data!E6 -> 1 | G8: =IF(B8=0,1-E8,E8) -> 1 | H8: =IF(B8<>0,IF(E8=1,"Hit","Miss"),IF(E8=1,"False alarm","Correct rejection")) -> Hit | I8: =IF(F8=G8,"","mismatch") | K8: False alarms (noise trial, said tilted) | L8: =COUNTIF(H4:H103,"False alarm") -> 2
A9: =Data!A7+1 -> 6 | B9: =Data!H7 -> -1 | C9: =ABS(B9) -> 1 | D9: =Data!D7 -> up | E9: =IF(D9="down",1,0) -> 0 | F9: =Data!E7 -> 0 | G9: =IF(B9=0,1-E9,E9) -> 0 | H9: =IF(B9<>0,IF(E9=1,"Hit","Miss"),IF(E9=1,"False alarm","Correct rejection")) -> Miss | I9: =IF(F9=G9,"","mismatch") | K9: Correct rejections (noise trial, said not tilted) | L9: =COUNTIF(H4:H103,"Correct rejection") -> 54
A10: =Data!A8+1 -> 7 | B10: =Data!H8 -> -4 | C10: =ABS(B10) -> 4 | D10: =Data!D8 -> up | E10: =IF(D10="down",1,0) -> 0 | F10: =Data!E8 -> 0 | G10: =IF(B10=0,1-E10,E10) -> 0 | H10: =IF(B10<>0,IF(E10=1,"Hit","Miss"),IF(E10=1,"False alarm","Correct rejection")) -> Miss | I10: =IF(F10=G10,"","mismatch") | K10: Hit rate = Hits / signal trials | L10: =L6/L4 -> 0.5
A11: =Data!A9+1 -> 8 | B11: =Data!H9 -> 0 | C11: =ABS(B11) -> 0 | D11: =Data!D9 -> down | E11: =IF(D11="down",1,0) -> 1 | F11: =Data!E9 -> 0 | G11: =IF(B11=0,1-E11,E11) -> 0 | H11: =IF(B11<>0,IF(E11=1,"Hit","Miss"),IF(E11=1,"False alarm","Correct rejection")) -> False alarm | I11: =IF(F11=G11,"","mismatch") | K11: False alarm rate = False alarms / noise trials | L11: =L8/L5 -> 0.035714286
A12: =Data!A10+1 -> 9 | B12: =Data!H10 -> 0 | C12: =ABS(B12) -> 0 | D12: =Data!D10 -> up | E12: =IF(D12="down",1,0) -> 0 | F12: =Data!E10 -> 1 | G12: =IF(B12=0,1-E12,E12) -> 1 | H12: =IF(B12<>0,IF(E12=1,"Hit","Miss"),IF(E12=1,"False alarm","Correct rejection")) -> Correct rejection | I12: =IF(F12=G12,"","mismatch") | K12: d' (sensitivity) = z(Hit rate) - z(False alarm rate) | L12: =NORMSINV(L10)-NORMSINV(L11) -> 1.8027431
A13: =Data!A11+1 -> 10 | B13: =Data!H11 -> 1 | C13: =ABS(B13) -> 1 | D13: =Data!D11 -> down | E13: =IF(D13="down",1,0) -> 1 | F13: =Data!E11 -> 1 | G13: =IF(B13=0,1-E13,E13) -> 1 | H13: =IF(B13<>0,IF(E13=1,"Hit","Miss"),IF(E13=1,"False alarm","Correct rejection")) -> Hit | I13: =IF(F13=G13,"","mismatch") | K13: Criterion c = -0.5 [z(Hit rate) + z(False alarm rate)] | L13: =-0.5*(NORMSINV(L10)+NORMSINV(L11)) -> 0.90137155
A14: =Data!A12+1 -> 11 | B14: =Data!H12 -> -2 | C14: =ABS(B14) -> 2 | D14: =Data!D12 -> up | E14: =IF(D14="down",1,0) -> 0 | F14: =Data!E12 -> 0 | G14: =IF(B14=0,1-E14,E14) -> 0 | H14: =IF(B14<>0,IF(E14=1,"Hit","Miss"),IF(E14=1,"False alarm","Correct rejection")) -> Miss | I14: =IF(F14=G14,"","mismatch")
A15: =Data!A13+1 -> 12 | B15: =Data!H13 -> -3 | C15: =ABS(B15) -> 3 | D15: =Data!D13 -> up | E15: =IF(D15="down",1,0) -> 0 | F15: =Data!E13 -> 0 | G15: =IF(B15=0,1-E15,E15) -> 0 | H15: =IF(B15<>0,IF(E15=1,"Hit","Miss"),IF(E15=1,"False alarm","Correct rejection")) -> Miss | I15: =IF(F15=G15,"","mismatch") | K15: Check with log-linear correction (not needed, no rate is 0 or 1)
A16: =Data!A14+1 -> 13 | B16: =Data!H14 -> 4 | C16: =ABS(B16) -> 4 | D16: =Data!D14 -> down | E16: =IF(D16="down",1,0) -> 1 | F16: =Data!E14 -> 1 | G16: =IF(B16=0,1-E16,E16) -> 1 | H16: =IF(B16<>0,IF(E16=1,"Hit","Miss"),IF(E16=1,"False alarm","Correct rejection")) -> Hit | I16: =IF(F16=G16,"","mismatch") | K16: Hit rate, corrected (Hits + 0.5) / (signal trials + 1) | L16: =(L6+0.5)/(L4+1) -> 0.5
A17: =Data!A15+1 -> 14 | B17: =Data!H15 -> 0 | C17: =ABS(B17) -> 0 | D17: =Data!D15 -> up | E17: =IF(D17="down",1,0) -> 0 | F17: =Data!E15 -> 1 | G17: =IF(B17=0,1-E17,E17) -> 1 | H17: =IF(B17<>0,IF(E17=1,"Hit","Miss"),IF(E17=1,"False alarm","Correct rejection")) -> Correct rejection | I17: =IF(F17=G17,"","mismatch") | K17: False alarm rate, corrected | L17: =(L8+0.5)/(L5+1) -> 0.043859649
A18: =Data!A16+1 -> 15 | B18: =Data!H16 -> 0 | C18: =ABS(B18) -> 0 | D18: =Data!D16 -> up | E18: =IF(D18="down",1,0) -> 0 | F18: =Data!E16 -> 1 | G18: =IF(B18=0,1-E18,E18) -> 1 | H18: =IF(B18<>0,IF(E18=1,"Hit","Miss"),IF(E18=1,"False alarm","Correct rejection")) -> Correct rejection | I18: =IF(F18=G18,"","mismatch") | K18: d' (corrected) | L18: =NORMSINV(L16)-NORMSINV(L17) -> 1.7075531
A19: =Data!A17+1 -> 16 | B19: =Data!H17 -> 0 | C19: =ABS(B19) -> 0 | D19: =Data!D17 -> up | E19: =IF(D19="down",1,0) -> 0 | F19: =Data!E17 -> 1 | G19: =IF(B19=0,1-E19,E19) -> 1 | H19: =IF(B19<>0,IF(E19=1,"Hit","Miss"),IF(E19=1,"False alarm","Correct rejection")) -> Correct rejection | I19: =IF(F19=G19,"","mismatch") | K19: c (corrected) | L19: =-0.5*(NORMSINV(L16)+NORMSINV(L17)) -> 0.85377655
A20: =Data!A18+1 -> 17 | B20: =Data!H18 -> 0 | C20: =ABS(B20) -> 0 | D20: =Data!D18 -> up | E20: =IF(D20="down",1,0) -> 0 | F20: =Data!E18 -> 1 | G20: =IF(B20=0,1-E20,E20) -> 1 | H20: =IF(B20<>0,IF(E20=1,"Hit","Miss"),IF(E20=1,"False alarm","Correct rejection")) -> Correct rejection | I20: =IF(F20=G20,"","mismatch")
A21: =Data!A19+1 -> 18 | B21: =Data!H19 -> 0 | C21: =ABS(B21) -> 0 | D21: =Data!D19 -> up | E21: =IF(D21="down",1,0) -> 0 | F21: =Data!E19 -> 1 | G21: =IF(B21=0,1-E21,E21) -> 1 | H21: =IF(B21<>0,IF(E21=1,"Hit","Miss"),IF(E21=1,"False alarm","Correct rejection")) -> Correct rejection | I21: =IF(F21=G21,"","mismatch") | K21: Accuracy
A22: =Data!A20+1 -> 19 | B22: =Data!H20 -> 0 | C22: =ABS(B22) -> 0 | D22: =Data!D20 -> up | E22: =IF(D22="down",1,0) -> 0 | F22: =Data!E20 -> 1 | G22: =IF(B22=0,1-E22,E22) -> 1 | H22: =IF(B22<>0,IF(E22=1,"Hit","Miss"),IF(E22=1,"False alarm","Correct rejection")) -> Correct rejection | I22: =IF(F22=G22,"","mismatch") | K22: Accuracy as recorded by PsychoPy | L22: =AVERAGE(F4:F103) -> 0.73
A23: =Data!A21+1 -> 20 | B23: =Data!H21 -> 1 | C23: =ABS(B23) -> 1 | D23: =Data!D21 -> down | E23: =IF(D23="down",1,0) -> 1 | F23: =Data!E21 -> 1 | G23: =IF(B23=0,1-E23,E23) -> 1 | H23: =IF(B23<>0,IF(E23=1,"Hit","Miss"),IF(E23=1,"False alarm","Correct rejection")) -> Hit | I23: =IF(F23=G23,"","mismatch") | K23: Accuracy re-scored with the rule (tilt = down, no tilt = up) | L23: =AVERAGE(G4:G103) -> 0.76
A24: =Data!A22+1 -> 21 | B24: =Data!H22 -> 3 | C24: =ABS(B24) -> 3 | D24: =Data!D22 -> down | E24: =IF(D24="down",1,0) -> 1 | F24: =Data!E22 -> 1 | G24: =IF(B24=0,1-E24,E24) -> 1 | H24: =IF(B24<>0,IF(E24=1,"Hit","Miss"),IF(E24=1,"False alarm","Correct rejection")) -> Hit | I24: =IF(F24=G24,"","mismatch") | K24: Trials where the two disagree | L24: =COUNTIF(I4:I103,"mismatch") -> 3
A25: =Data!A23+1 -> 22 | B25: =Data!H23 -> 0 | C25: =ABS(B25) -> 0 | D25: =Data!D23 -> up | E25: =IF(D25="down",1,0) -> 0 | F25: =Data!E23 -> 1 | G25: =IF(B25=0,1-E25,E25) -> 1 | H25: =IF(B25<>0,IF(E25=1,"Hit","Miss"),IF(E25=1,"False alarm","Correct rejection")) -> Correct rejection | I25: =IF(F25=G25,"","mismatch") | K25: Mean response time (s) | L25: =AVERAGE(Data!F2:F101) -> 0.75514498
A26: =Data!A24+1 -> 23 | B26: =Data!H24 -> -5 | C26: =ABS(B26) -> 5 | D26: =Data!D24 -> down | E26: =IF(D26="down",1,0) -> 1 | F26: =Data!E24 -> 1 | G26: =IF(B26=0,1-E26,E26) -> 1 | H26: =IF(B26<>0,IF(E26=1,"Hit","Miss"),IF(E26=1,"False alarm","Correct rejection")) -> Hit | I26: =IF(F26=G26,"","mismatch") | K26: Mean response time, correct trials (s) | L26: =AVERAGEIF(G4:G103,1,Data!F2:F101) -> 0.68805288
A27: =Data!A25+1 -> 24 | B27: =Data!H25 -> 0 | C27: =ABS(B27) -> 0 | D27: =Data!D25 -> up | E27: =IF(D27="down",1,0) -> 0 | F27: =Data!E25 -> 1 | G27: =IF(B27=0,1-E27,E27) -> 1 | H27: =IF(B27<>0,IF(E27=1,"Hit","Miss"),IF(E27=1,"False alarm","Correct rejection")) -> Correct rejection | I27: =IF(F27=G27,"","mismatch") | K27: Mean response time, incorrect trials (s) | L27: =AVERAGEIF(G4:G103,0,Data!F2:F101) -> 0.96760329
A28: =Data!A26+1 -> 25 | B28: =Data!H26 -> 2 | C28: =ABS(B28) -> 2 | D28: =Data!D26 -> down | E28: =IF(D28="down",1,0) -> 1 | F28: =Data!E26 -> 1 | G28: =IF(B28=0,1-E28,E28) -> 1 | H28: =IF(B28<>0,IF(E28=1,"Hit","Miss"),IF(E28=1,"False alarm","Correct rejection")) -> Hit | I28: =IF(F28=G28,"","mismatch")
A29: =Data!A27+1 -> 26 | B29: =Data!H27 -> 0 | C29: =ABS(B29) -> 0 | D29: =Data!D27 -> up | E29: =IF(D29="down",1,0) -> 0 | F29: =Data!E27 -> 1 | G29: =IF(B29=0,1-E29,E29) -> 1 | H29: =IF(B29<>0,IF(E29=1,"Hit","Miss"),IF(E29=1,"False alarm","Correct rejection")) -> Correct rejection | I29: =IF(F29=G29,"","mismatch")
A30: =Data!A28+1 -> 27 | B30: =Data!H28 -> 0 | C30: =ABS(B30) -> 0 | D30: =Data!D28 -> up | E30: =IF(D30="down",1,0) -> 0 | F30: =Data!E28 -> 1 | G30: =IF(B30=0,1-E30,E30) -> 1 | H30: =IF(B30<>0,IF(E30=1,"Hit","Miss"),IF(E30=1,"False alarm","Correct rejection")) -> Correct rejection | I30: =IF(F30=G30,"","mismatch") | K30: Proportion of "tilted" responses by size of tilt
A31: =Data!A29+1 -> 28 | B31: =Data!H29 -> -3 | C31: =ABS(B31) -> 3 | D31: =Data!D29 -> down | E31: =IF(D31="down",1,0) -> 1 | F31: =Data!E29 -> 1 | G31: =IF(B31=0,1-E31,E31) -> 1 | H31: =IF(B31<>0,IF(E31=1,"Hit","Miss"),IF(E31=1,"False alarm","Correct rejection")) -> Hit | I31: =IF(F31=G31,"","mismatch") | K31: Size of tilt (deg) | L31: Trials | M31: Said "tilted" | N31: Proportion
A32: =Data!A30+1 -> 29 | B32: =Data!H30 -> 0 | C32: =ABS(B32) -> 0 | D32: =Data!D30 -> up | E32: =IF(D32="down",1,0) -> 0 | F32: =Data!E30 -> 1 | G32: =IF(B32=0,1-E32,E32) -> 1 | H32: =IF(B32<>0,IF(E32=1,"Hit","Miss"),IF(E32=1,"False alarm","Correct rejection")) -> Correct rejection | I32: =IF(F32=G32,"","mismatch") | K32: 0 | L32: =COUNTIF($C$4:$C$103,K32) -> 56 | M32: =SUMIF($C$4:$C$103,K32,$E$4:$E$103) -> 2 | N32: =M32/L32 -> 0.035714286
A33: =Data!A31+1 -> 30 | B33: =Data!H31 -> 3 | C33: =ABS(B33) -> 3 | D33: =Data!D31 -> down | E33: =IF(D33="down",1,0) -> 1 | F33: =Data!E31 -> 1 | G33: =IF(B33=0,1-E33,E33) -> 1 | H33: =IF(B33<>0,IF(E33=1,"Hit","Miss"),IF(E33=1,"False alarm","Correct rejection")) -> Hit | I33: =IF(F33=G33,"","mismatch") | K33: 1 | L33: =COUNTIF($C$4:$C$103,K33) -> 10 | M33: =SUMIF($C$4:$C$103,K33,$E$4:$E$103) -> 3 | N33: =M33/L33 -> 0.3
A34: =Data!A32+1 -> 31 | B34: =Data!H32 -> 0 | C34: =ABS(B34) -> 0 | D34: =Data!D32 -> up | E34: =IF(D34="down",1,0) -> 0 | F34: =Data!E32 -> 1 | G34: =IF(B34=0,1-E34,E34) -> 1 | H34: =IF(B34<>0,IF(E34=1,"Hit","Miss"),IF(E34=1,"False alarm","Correct rejection")) -> Correct rejection | I34: =IF(F34=G34,"","mismatch") | K34: 2 | L34: =COUNTIF($C$4:$C$103,K34) -> 10 | M34: =SUMIF($C$4:$C$103,K34,$E$4:$E$103) -> 3 | N34: =M34/L34 -> 0.3
A35: =Data!A33+1 -> 32 | B35: =Data!H33 -> -1 | C35: =ABS(B35) -> 1 | D35: =Data!D33 -> down | E35: =IF(D35="down",1,0) -> 1 | F35: =Data!E33 -> 1 | G35: =IF(B35=0,1-E35,E35) -> 1 | H35: =IF(B35<>0,IF(E35=1,"Hit","Miss"),IF(E35=1,"False alarm","Correct rejection")) -> Hit | I35: =IF(F35=G35,"","mismatch") | K35: 3 | L35: =COUNTIF($C$4:$C$103,K35) -> 10 | M35: =SUMIF($C$4:$C$103,K35,$E$4:$E$103) -> 6 | N35: =M35/L35 -> 0.6
A36: =Data!A34+1 -> 33 | B36: =Data!H34 -> 0 | C36: =ABS(B36) -> 0 | D36: =Data!D34 -> up | E36: =IF(D36="down",1,0) -> 0 | F36: =Data!E34 -> 1 | G36: =IF(B36=0,1-E36,E36) -> 1 | H36: =IF(B36<>0,IF(E36=1,"Hit","Miss"),IF(E36=1,"False alarm","Correct rejection")) -> Correct rejection | I36: =IF(F36=G36,"","mismatch") | K36: 4 | L36: =COUNTIF($C$4:$C$103,K36) -> 10 | M36: =SUMIF($C$4:$C$103,K36,$E$4:$E$103) -> 6 | N36: =M36/L36 -> 0.6
A37: =Data!A35+1 -> 34 | B37: =Data!H35 -> 0 | C37: =ABS(B37) -> 0 | D37: =Data!D35 -> up | E37: =IF(D37="down",1,0) -> 0 | F37: =Data!E35 -> 1 | G37: =IF(B37=0,1-E37,E37) -> 1 | H37: =IF(B37<>0,IF(E37=1,"Hit","Miss"),IF(E37=1,"False alarm","Correct rejection")) -> Correct rejection | I37: =IF(F37=G37,"","mismatch") | K37: 5 | L37: =COUNTIF($C$4:$C$103,K37) -> 4 | M37: =SUMIF($C$4:$C$103,K37,$E$4:$E$103) -> 4 | N37: =M37/L37 -> 1
A38: =Data!A36+1 -> 35 | B38: =Data!H36 -> 0 | C38: =ABS(B38) -> 0 | D38: =Data!D36 -> up | E38: =IF(D38="down",1,0) -> 0 | F38: =Data!E36 -> 1 | G38: =IF(B38=0,1-E38,E38) -> 1 | H38: =IF(B38<>0,IF(E38=1,"Hit","Miss"),IF(E38=1,"False alarm","Correct rejection")) -> Correct rejection | I38: =IF(F38=G38,"","mismatch")
A39: =Data!A37+1 -> 36 | B39: =Data!H37 -> 0 | C39: =ABS(B39) -> 0 | D39: =Data!D37 -> up | E39: =IF(D39="down",1,0) -> 0 | F39: =Data!E37 -> 1 | G39: =IF(B39=0,1-E39,E39) -> 1 | H39: =IF(B39<>0,IF(E39=1,"Hit","Miss"),IF(E39=1,"False alarm","Correct rejection")) -> Correct rejection | I39: =IF(F39=G39,"","mismatch") | K39: Tilt at which "tilted" responses reach 50% (linear interpolation between 2 and 3 deg) | L39: =2+(0.5-N34)/(N35-N34) -> 2.6666667
A40: =Data!A38+1 -> 37 | B40: =Data!H38 -> -5 | C40: =ABS(B40) -> 5 | D40: =Data!D38 -> down | E40: =IF(D40="down",1,0) -> 1 | F40: =Data!E38 -> 1 | G40: =IF(B40=0,1-E40,E40) -> 1 | H40: =IF(B40<>0,IF(E40=1,"Hit","Miss"),IF(E40=1,"False alarm","Correct rejection")) -> Hit | I40: =IF(F40=G40,"","mismatch")
...

Sheet Figures
A1: Figures (identical to the figures in the lab report)
A16: Figure 1. Stimulus - Sinusoidal grating with a Gaussian mask (shown with a 5 degree tilt)
A34: Figure 2. Number of hits, misses, false alarms and correct rejections over the 100 trials.
A53: Figure 3. Proportion of "tilted" responses at each size of tilt over the 100 trials.
